Workbook

Sheet 元データ
A1: ApplyReceptionNo | B1: ApplyStaffId | C1: ApplyStaffName | D1: CenterMatterStatusCD | E1: CenterMatterStatusName | F1: HistoryExistCD | G1: HistoryExistName | H1: ReasonGenerateDate | I1: ApplyDate | J1: ApplyReceptionDate | K1: ContactPersonRegistDate | L1: ApprovedRegistDate | M1: ApplyDataOutputDate | N1: CompletedRegistDate | O1: CenterProcessTypeText | P1: hasTenpu | Q1: hasJyumin | R1: hasHassin | S1: hasKakunin | T1: hasKanri | U1: hasSV | V1: hasData | W1: hasSakujyo | X1: hasTokubetsu | Y1: hasTokubetsu1 | Z1: hasTokubetsu2 | AA1: hasTokubetsu3 | AB1: NotificationReasonCD | AC1: NotificationReasonKbn | AD1: NotificationReasonKbnText | AE1: NotificationReasonKbnContent | AF1: AlimonyFlg | AG1: HealthInsuranceFlg | AH1: TaxBiteFlg | AI1: cancelFlgText | AJ1: TemporaryText | AK1: ApplyContent | AL1: ★最下行 | AM1: ★経過日数 | AN1: ★未完了 | AO1: ★共済あり
A2: 200860002045 | D2: 31 | E2: 31 ＯＰ確認中 | H2: 39904 | I2: 39898 | J2: 41984 | K2: 41984 | O2: 21 担当者登録 | AB2: 47 | AC2: 0 | AD2: 減 | AE2: 47 扶養親族の就職 | AF2: 減 | AG2: 減 | AH2: 減 | AK2: 対応不要 該当職員無し | AL2: =IF(A2="","",IF(COUNTIF(A2:A$2001,A2)=1,1,0)) -> 1 | AM2: =IF(I2="","",TODAY()-I2) -> 6392 | AN2: =IF(A2="","",IF(AND(E2<>"33 確認済",E2<>"36 送付中"),1,0)) -> 1 | AO2: =IF(A2="","",IF(AG2<>"",1,0)) -> 1
A3: 200860002058 | D3: 31 | E3: 31 ＯＰ確認中 | H3: 39872 | I3: 39898 | J3: 41984 | K3: 41984 | O3: 21 担当者登録 | AB3: 22 | AC3: 1 | AD3: 増 | AE3: 22 扶養親族の退職 | AG3: 増 | AK3: 対応不要 | AL3: =IF(A3="","",IF(COUNTIF(A3:A$2001,A3)=1,1,0)) -> 1 | AM3: =IF(I3="","",TODAY()-I3) -> 6392 | AN3: =IF(A3="","",IF(AND(E3<>"33 確認済",E3<>"36 送付中"),1,0)) -> 1 | AO3: =IF(A3="","",IF(AG3<>"",1,0)) -> 1
A4: 200960002795 | D4: 40 | E4: 40 差戻し | F4: 20 | G4: 20 差戻し | H4: 30829 | I4: 40233 | J4: 40234 | K4: 40238 | O4: 40 ＳＶ承認 | AB4: 23 | AC4: 1 | AD4: 増 | AE4: 23 本人の結婚 | AL4: =IF(A4="","",IF(COUNTIF(A4:A$2001,A4)=1,1,0)) -> 0 | AM4: =IF(I4="","",TODAY()-I4) -> 6057 | AN4: =IF(A4="","",IF(AND(E4<>"33 確認済",E4<>"36 送付中"),1,0)) -> 1 | AO4: =IF(A4="","",IF(AG4<>"",1,0)) -> 0
A5: 200960002795 | D5: 40 | E5: 40 差戻し | F5: 20 | G5: 20 差戻し | H5: 30829 | I5: 40233 | J5: 40234 | K5: 40238 | O5: 40 ＳＶ承認 | AB5: 23 | AC5: 1 | AD5: 増 | AE5: 23 結婚 | AL5: =IF(A5="","",IF(COUNTIF(A5:A$2001,A5)=1,1,0)) -> 1 | AM5: =IF(I5="","",TODAY()-I5) -> 6057 | AN5: =IF(A5="","",IF(AND(E5<>"33 確認済",E5<>"36 送付中"),1,0)) -> 1 | AO5: =IF(A5="","",IF(AG5<>"",1,0)) -> 0
A6: 200960002929 | D6: 31 | E6: 31 ＯＰ確認中 | H6: 40251 | I6: 40252 | J6: 41984 | K6: 41984 | O6: 21 担当者登録 | AB6: 25 | AC6: 1 | AD6: 増 | AE6: 25 育休 | AL6: =IF(A6="","",IF(COUNTIF(A6:A$2001,A6)=1,1,0)) -> 1 | AM6: =IF(I6="","",TODAY()-I6) -> 6038 | AN6: =IF(A6="","",IF(AND(E6<>"33 確認済",E6<>"36 送付中"),1,0)) -> 1 | AO6: =IF(A6="","",IF(AG6<>"",1,0)) -> 0
A7: 200960002933 | D7: 31 | E7: 31 ＯＰ確認中 | H7: 40238 | I7: 40253 | J7: 41984 | K7: 41984 | O7: 21 担当者登録 | AB7: 21 | AC7: 1 | AD7: 増 | AE7: 21 出生 | AF7: 増 | AG7: 増 | AH7: 増 | AL7: =IF(A7="","",IF(COUNTIF(A7:A$2001,A7)=1,1,0)) -> 1 | AM7: =IF(I7="","",TODAY()-I7) -> 6037 | AN7: =IF(A7="","",IF(AND(E7<>"33 確認済",E7<>"36 送付中"),1,0)) -> 1 | AO7: =IF(A7="","",IF(AG7<>"",1,0)) -> 1
A8: 200960002999 | D8: 31 | E8: 31 ＯＰ確認中 | H8: 40238 | I8: 40262 | J8: 40266 | K8: 40266 | O8: 22 担当者変更 | AB8: 26 | AC8: 1 | AD8: 増 | AE8: 26 扶養者の変更 | AF8: 増 | AG8: 増 | AH8: 増 | AL8: =IF(A8="","",IF(COUNTIF(A8:A$2001,A8)=1,1,0)) -> 1 | AM8: =IF(I8="","",TODAY()-I8) -> 6028 | AN8: =IF(A8="","",IF(AND(E8<>"33 確認済",E8<>"36 送付中"),1,0)) -> 1 | AO8: =IF(A8="","",IF(AG8<>"",1,0)) -> 1
A9: 200960003028 | D9: 31 | E9: 31 ＯＰ確認中 | H9: 40254 | I9: 40266 | J9: 40267 | K9: 40616 | O9: 22 担当者変更 | S9: 確 | AB9: 23 | AC9: 1 | AD9: 増 | AE9: 23 本人の結婚 | AL9: =IF(A9="","",IF(COUNTIF(A9:A$2001,A9)=1,1,0)) -> 0 | AM9: =IF(I9="","",TODAY()-I9) -> 6024 | AN9: =IF(A9="","",IF(AND(E9<>"33 確認済",E9<>"36 送付中"),1,0)) -> 1 | AO9: =IF(A9="","",IF(AG9<>"",1,0)) -> 0
A10: 200960003028 | D10: 31 | E10: 31 ＯＰ確認中 | H10: 40254 | I10: 40266 | J10: 40267 | K10: 40616 | O10: 22 担当者変更 | S10: 確 | AB10: 23 | AC10: 1 | AD10: 増 | AE10: 23 結婚 | AL10: =IF(A10="","",IF(COUNTIF(A10:A$2001,A10)=1,1,0)) -> 1 | AM10: =IF(I10="","",TODAY()-I10) -> 6024 | AN10: =IF(A10="","",IF(AND(E10<>"33 確認済",E10<>"36 送付中"),1,0)) -> 1 | AO10: =IF(A10="","",IF(AG10<>"",1,0)) -> 0
A11: 201060000063 | D11: 31 | E11: 31 ＯＰ確認中 | F11: 20 | G11: 20 差戻し | H11: 40268 | I11: 40270 | J11: 41984 | K11: 41984 | O11: 21 担当者登録 | AB11: 50 | AC11: 0 | AD11: 減 | AE11: 50 扶養者の変更 | AF11: 減 | AG11: 減 | AH11: 減 | AL11: =IF(A11="","",IF(COUNTIF(A11:A$2001,A11)=1,1,0)) -> 1 | AM11: =IF(I11="","",TODAY()-I11) -> 6020 | AN11: =IF(A11="","",IF(AND(E11<>"33 確認済",E11<>"36 送付中"),1,0)) -> 1 | AO11: =IF(A11="","",IF(AG11<>"",1,0)) -> 1
A12: 201060002518 | D12: 40 | E12: 40 差戻し | F12: 20 | G12: 20 差戻し | H12: 40273 | I12: 40574 | J12: 40617 | K12: 40617 | O12: 40 ＳＶ承認 | P12: 添 | AB12: 99 | AC12: 1 | AD12: 増 | AE12: 99 その他 | AF12: 増 | AG12: 増 | AL12: =IF(A12="","",IF(COUNTIF(A12:A$2001,A12)=1,1,0)) -> 1 | AM12: =IF(I12="","",TODAY()-I12) -> 5716 | AN12: =IF(A12="","",IF(AND(E12<>"33 確認済",E12<>"36 送付中"),1,0)) -> 1 | AO12: =IF(A12="","",IF(AG12<>"",1,0)) -> 1
A13: 201160000813 | D13: 31 | E13: 31 ＯＰ確認中 | F13: 20 | G13: 20 差戻し | H13: 40634 | I13: 40721 | J13: 41984 | K13: 41984 | O13: 21 担当者登録 | AB13: 47 | AC13: 0 | AD13: 減 | AE13: 47 扶養親族の就職 | AG13: 減 | AL13: =IF(A13="","",IF(COUNTIF(A13:A$2001,A13)=1,1,0)) -> 1 | AM13: =IF(I13="","",TODAY()-I13) -> 5569 | AN13: =IF(A13="","",IF(AND(E13<>"33 確認済",E13<>"36 送付中"),1,0)) -> 1 | AO13: =IF(A13="","",IF(AG13<>"",1,0)) -> 1
A14: 201260002213 | D14: 31 | E14: 31 ＯＰ確認中 | H14: 41259 | I14: 41260 | J14: 41984 | K14: 41984 | O14: 21 担当者登録 | AB14: 22 | AC14: 1 | AD14: 増 | AE14: 22 扶養親族の退職 | AF14: 増 | AG14: 増 | AH14: 増 | AL14: =IF(A14="","",IF(COUNTIF(A14:A$2001,A14)=1,1,0)) -> 1 | AM14: =IF(I14="","",TODAY()-I14) -> 5030 | AN14: =IF(A14="","",IF(AND(E14<>"33 確認済",E14<>"36 送付中"),1,0)) -> 1 | AO14: =IF(A14="","",IF(AG14<>"",1,0)) -> 1
A15: 201260002232 | D15: 31 | E15: 31 ＯＰ確認中 | H15: 41258 | I15: 41262 | J15: 41984 | K15: 41984 | O15: 21 担当者登録 | AB15: 22 | AC15: 1 | AD15: 増 | AE15: 22 扶養親族の退職 | AF15: 増 | AG15: 増 | AH15: 増 | AL15: =IF(A15="","",IF(COUNTIF(A15:A$2001,A15)=1,1,0)) -> 1 | AM15: =IF(I15="","",TODAY()-I15) -> 5028 | AN15: =IF(A15="","",IF(AND(E15<>"33 確認済",E15<>"36 送付中"),1,0)) -> 1 | AO15: =IF(A15="","",IF(AG15<>"",1,0)) -> 1
A16: 201260002479 | D16: 31 | E16: 31 ＯＰ確認中 | H16: 41309 | I16: 41309 | J16: 41984 | K16: 41984 | O16: 21 担当者登録 | AB16: 26 | AC16: 1 | AD16: 増 | AE16: 26 扶養者の変更 | AG16: 増 | AL16: =IF(A16="","",IF(COUNTIF(A16:A$2001,A16)=1,1,0)) -> 1 | AM16: =IF(I16="","",TODAY()-I16) -> 4981 | AN16: =IF(A16="","",IF(AND(E16<>"33 確認済",E16<>"36 送付中"),1,0)) -> 1 | AO16: =IF(A16="","",IF(AG16<>"",1,0)) -> 1
A17: 201360001338 | D17: 40 | E17: 40 差戻し | F17: 20 | G17: 20 差戻し | H17: 41518 | I17: 41554 | J17: 41554 | K17: 41554 | O17: 57 削除待ち登録 | W17: 削 | AB17: 47 | AC17: 0 | AD17: 減 | AE17: 47 扶養親族の就職 | AH17: 減 | AL17: =IF(A17="","",IF(COUNTIF(A17:A$2001,A17)=1,1,0)) -> 1 | AM17: =IF(I17="","",TODAY()-I17) -> 4736 | AN17: =IF(A17="","",IF(AND(E17<>"33 確認済",E17<>"36 送付中"),1,0)) -> 1 | AO17: =IF(A17="","",IF(AG17<>"",1,0)) -> 0
A18: 201360002263 | D18: 40 | E18: 40 差戻し | F18: 20 | G18: 20 差戻し | H18: 41646 | I18: 41647 | J18: 41648 | K18: 41648 | O18: 57 削除待ち登録 | W18: 削 | AB18: 23 | AC18: 1 | AD18: 増 | AE18: 23 本人の結婚 | AF18: 増 | AG18: 増 | AH18: 増 | AL18: =IF(A18="","",IF(COUNTIF(A18:A$2001,A18)=1,1,0)) -> 0 | AM18: =IF(I18="","",TODAY()-I18) -> 4643 | AN18: =IF(A18="","",IF(AND(E18<>"33 確認済",E18<>"36 送付中"),1,0)) -> 1 | AO18: =IF(A18="","",IF(AG18<>"",1,0)) -> 1
A19: 201360002263 | D19: 40 | E19: 40 差戻し | F19: 20 | G19: 20 差戻し | H19: 41646 | I19: 41647 | J19: 41648 | K19: 41648 | O19: 57 削除待ち登録 | W19: 削 | AB19: 23 | AC19: 1 | AD19: 増 | AE19: 23 結婚 | AF19: 増 | AG19: 増 | AH19: 増 | AL19: =IF(A19="","",IF(COUNTIF(A19:A$2001,A19)=1,1,0)) -> 1 | AM19: =IF(I19="","",TODAY()-I19) -> 4643 | AN19: =IF(A19="","",IF(AND(E19<>"33 確認済",E19<>"36 送付中"),1,0)) -> 1 | AO19: =IF(A19="","",IF(AG19<>"",1,0)) -> 1
A20: 201460000430 | D20: 31 | E20: 31 ＯＰ確認中 | H20: 41754 | I20: 41754 | J20: 41985 | K20: 41985 | O20: 21 担当者登録 | AB20: 47 | AC20: 0 | AD20: 減 | AE20: 47 扶養親族の就職 | AF20: 減 | AG20: 減 | AH20: 減 | AL20: =IF(A20="","",IF(COUNTIF(A20:A$2001,A20)=1,1,0)) -> 1 | AM20: =IF(I20="","",TODAY()-I20) -> 4536 | AN20: =IF(A20="","",IF(AND(E20<>"33 確認済",E20<>"36 送付中"),1,0)) -> 1 | AO20: =IF(A20="","",IF(AG20<>"",1,0)) -> 1
A21: 201560001259 | D21: 31 | E21: 31 ＯＰ確認中 | H21: 42189 | I21: 42230 | J21: 42431 | K21: 42431 | O21: 21 担当者登録 | T21: 管 | AB21: 99 | AC21: 1 | AD21: 増 | AE21: 99 その他 | AF21: 増 | AH21: 増 | AL21: =IF(A21="","",IF(COUNTIF(A21:A$2001,A21)=1,1,0)) -> 1 | AM21: =IF(I21="","",TODAY()-I21) -> 4060 | AN21: =IF(A21="","",IF(AND(E21<>"33 確認済",E21<>"36 送付中"),1,0)) -> 1 | AO21: =IF(A21="","",IF(AG21<>"",1,0)) -> 0
A22: 201560002704 | D22: 40 | E22: 40 差戻し | F22: 20 | G22: 20 差戻し | H22: 42370 | I22: 42408 | J22: 42408 | K22: 42408 | O22: 57 削除待ち登録 | W22: 削 | AB22: 99 | AC22: 0 | AD22: 減 | AE22: 99 その他 | AH22: 減 | AL22: =IF(A22="","",IF(COUNTIF(A22:A$2001,A22)=1,1,0)) -> 1 | AM22: =IF(I22="","",TODAY()-I22) -> 3882 | AN22: =IF(A22="","",IF(AND(E22<>"33 確認済",E22<>"36 送付中"),1,0)) -> 1 | AO22: =IF(A22="","",IF(AG22<>"",1,0)) -> 0
A23: 201660002819 | D23: 40 | E23: 40 差戻し | F23: 20 | G23: 20 差戻し | H23: 42566 | I23: 42732 | J23: 42739 | K23: 42739 | O23: 57 削除待ち登録 | W23: 削 | AB23: 9 | AC23: 0 | AD23: 減 | AE23: 09 死亡 | AF23: 減 | AG23: 減 | AH23: 減 | AL23: =IF(A23="","",IF(COUNTIF(A23:A$2001,A23)=1,1,0)) -> 1 | AM23: =IF(I23="","",TODAY()-I23) -> 3558 | AN23: =IF(A23="","",IF(AND(E23<>"33 確認済",E23<>"36 送付中"),1,0)) -> 1 | AO23: =IF(A23="","",IF(AG23<>"",1,0)) -> 1
A24: 201760002086 | D24: 40 | E24: 40 差戻し | F24: 20 | G24: 20 差戻し | H24: 43031 | I24: 43036 | J24: 43038 | K24: 43041 | O24: 57 削除待ち登録 | W24: 削 | AB24: 27 | AC24: 1 | AD24: 増 | AE24: 27 収入限度額以下 | AH24: 増 | AL24: =IF(A24="","",IF(COUNTIF(A24:A$2001,A24)=1,1,0)) -> 1 | AM24: =IF(I24="","",TODAY()-I24) -> 3254 | AN24: =IF(A24="","",IF(AND(E24<>"33 確認済",E24<>"36 送付中"),1,0)) -> 1 | AO24: =IF(A24="","",IF(AG24<>"",1,0)) -> 0
A25: 201860001388 | D25: 40 | E25: 40 差戻し | F25: 20 | G25: 20 差戻し | H25: 43321 | I25: 43321 | J25: 43325 | K25: 43325 | O25: 55 添付書類待ち登録 | P25: 添 | U25: Ｓ | AB25: 21 | AC25: 1 | AD25: 増 | AE25: 21 出生 | AG25: 増 | AL25: =IF(A25="","",IF(COUNTIF(A25:A$2001,A25)=1,1,0)) -> 1 | AM25: =IF(I25="","",TODAY()-I25) -> 2969 | AN25: =IF(A25="","",IF(AND(E25<>"33 確認済",E25<>"36 送付中"),1,0)) -> 1 | AO25: =IF(A25="","",IF(AG25<>"",1,0)) -> 1
A26: 201860001862 | D26: 31 | E26: 31 ＯＰ確認中 | H26: 43341 | I26: 43371 | J26: 43411 | K26: 43411 | O26: 21 担当者登録 | AB26: 9 | AC26: 0 | AD26: 減 | AE26: 09 死亡 | AF26: 減 | AG26: 減 | AH26: 減 | AL26: =IF(A26="","",IF(COUNTIF(A26:A$2001,A26)=1,1,0)) -> 1 | AM26: =IF(I26="","",TODAY()-I26) -> 2919 | AN26: =IF(A26="","",IF(AND(E26<>"33 確認済",E26<>"36 送付中"),1,0)) -> 1 | AO26: =IF(A26="","",IF(AG26<>"",1,0)) -> 1
A27: 202060000569 | D27: 31 | E27: 31 ＯＰ確認中 | H27: 43937 | I27: 43951 | J27: 44013 | K27: 44013 | O27: 21 担当者登録 | AB27: 22 | AC27: 1 | AD27: 増 | AE27: 22 扶養親族の退職 | AG27: 増 | AL27: =IF(A27="","",IF(COUNTIF(A27:A$2001,A27)=1,1,0)) -> 1 | AM27: =IF(I27="","",TODAY()-I27) -> 2339 | AN27: =IF(A27="","",IF(AND(E27<>"33 確認済",E27<>"36 送付中"),1,0)) -> 1 | AO27: =IF(A27="","",IF(AG27<>"",1,0)) -> 1
A28: 202060001460 | D28: 40 | E28: 40 差戻し | F28: 20 | G28: 20 差戻し | H28: 43191 | I28: 44139 | J28: 44501 | K28: 44504 | O28: 55 添付書類待ち登録 | P28: 添 | AB28: 27 | AC28: 1 | AD28: 増 | AE28: 27 収入限度額以下 | AF28: 増 | AG28: 増 | AH28: 増 | AL28: =IF(A28="","",IF(COUNTIF(A28:A$2001,A28)=1,1,0)) -> 1 | AM28: =IF(I28="","",TODAY()-I28) -> 2151 | AN28: =IF(A28="","",IF(AND(E28<>"33 確認済",E28<>"36 送付中"),1,0)) -> 1 | AO28: =IF(A28="","",IF(AG28<>"",1,0)) -> 1
A29: 202060002466 | D29: 20 | E29: 20 確認待ち | F29: 20 | G29: 20 差戻し | H29: 44197 | I29: 44210 | J29: 44243 | K29: 45617 | O29: 99 データメンテナンス | R29: 発 | W29: 削 | AB29: 27 | AC29: 1 | AD29: 増 | AE29: 27 収入限度額以下 | AF29: 増 | AG29: 増 | AL29: =IF(A29="","",IF(COUNTIF(A29:A$2001,A29)=1,1,0)) -> 1 | AM29: =IF(I29="","",TODAY()-I29) -> 2080 | AN29: =IF(A29="","",IF(AND(E29<>"33 確認済",E29<>"36 送付中"),1,0)) -> 1 | AO29: =IF(A29="","",IF(AG29<>"",1,0)) -> 1
A30: 202060002824 | D30: 40 | E30: 40 差戻し | F30: 20 | G30: 20 差戻し | H30: 43497 | I30: 44232 | J30: 44236 | K30: 44236 | O30: 57 削除待ち登録 | W30: 削 | AB30: 51 | AC30: 0 | AD30: 減 | AE30: 51 収入限度額以上 | AF30: 減 | AG30: 減 | AL30: =IF(A30="","",IF(COUNTIF(A30:A$2001,A30)=1,1,0)) -> 1 | AM30: =IF(I30="","",TODAY()-I30) -> 2058 | AN30: =IF(A30="","",IF(AND(E30<>"33 確認済",E30<>"36 送付中"),1,0)) -> 1 | AO30: =IF(A30="","",IF(AG30<>"",1,0)) -> 1
A31: 202060003171 | D31: 31 | E31: 31 ＯＰ確認中 | H31: 44280 | I31: 44281 | J31: 44302 | K31: 44302 | O31: 21 担当者登録 | AB31: 50 | AC31: 0 | AD31: 減 | AE31: 50 扶養者の変更 | AF31: 減 | AG31: 減 | AH31: 減 | AL31: =IF(A31="","",IF(COUNTIF(A31:A$2001,A31)=1,1,0)) -> 1 | AM31: =IF(I31="","",TODAY()-I31) -> 2009 | AN31: =IF(A31="","",IF(AND(E31<>"33 確認済",E31<>"36 送付中"),1,0)) -> 1 | AO31: =IF(A31="","",IF(AG31<>"",1,0)) -> 1
A32: 202360000913 | D32: 31 | E32: 31 ＯＰ確認中 | H32: 45062 | I32: 45096 | J32: 45098 | K32: 45148 | O32: 21 担当者登録 | AB32: 3 | AC32: 0 | AD32: 減 | AE32: 03 離婚 | AL32: =IF(A32="","",IF(COUNTIF(A32:A$2001,A32)=1,1,0)) -> 1 | AM32: =IF(I32="","",TODAY()-I32) -> 1194 | AN32: =IF(A32="","",IF(AND(E32<>"33 確認済",E32<>"36 送付中"),1,0)) -> 1 | AO32: =IF(A32="","",IF(AG32<>"",1,0)) -> 0
A33: 202360003315 | D33: 31 | E33: 31 ＯＰ確認中 | H33: 45370 | I33: 45370 | J33: 45575 | K33: 45575 | O33: 21 担当者登録 | AB33: 50 | AC33: 0 | AD33: 減 | AE33: 50 扶養者の変更 | AF33: 減 | AG33: 減 | AH33: 減 | AL33: =IF(A33="","",IF(COUNTIF(A33:A$2001,A33)=1,1,0)) -> 1 | AM33: =IF(I33="","",TODAY()-I33) -> 920 | AN33: =IF(A33="","",IF(AND(E33<>"33 確認済",E33<>"36 送付中"),1,0)) -> 1 | AO33: =IF(A33="","",IF(AG33<>"",1,0)) -> 1
A34: 202360003320 | D34: 31 | E34: 31 ＯＰ確認中 | H34: 45352 | I34: 45370 | J34: 45373 | K34: 45373 | O34: 22 担当者変更 | AB34: 23 | AC34: 1 | AD34: 増 | AE34: 23 本人の結婚 | AL34: =IF(A34="","",IF(COUNTIF(A34:A$2001,A34)=1,1,0)) -> 0 | AM34: =IF(I34="","",TODAY()-I34) -> 920 | AN34: =IF(A34="","",IF(AND(E34<>"33 確認済",E34<>"36 送付中"),1,0)) -> 1 | AO34: =IF(A34="","",IF(AG34<>"",1,0)) -> 0
A35: 202360003320 | D35: 31 | E35: 31 ＯＰ確認中 | H35: 45352 | I35: 45370 | J35: 45373 | K35: 45373 | O35: 22 担当者変更 | AB35: 23 | AC35: 1 | AD35: 増 | AE35: 23 結婚 | AL35: =IF(A35="","",IF(COUNTIF(A35:A$2001,A35)=1,1,0)) -> 1 | AM35: =IF(I35="","",TODAY()-I35) -> 920 | AN35: =IF(A35="","",IF(AND(E35<>"33 確認済",E35<>"36 送付中"),1,0)) -> 1 | AO35: =IF(A35="","",IF(AG35<>"",1,0)) -> 0
A36: 202460000110 | D36: 20 | E36: 20 確認待ち | F36: 20 | G36: 20 差戻し | H36: 45383 | I36: 45405 | J36: 45387 | K36: 45617 | O36: 57 削除待ち登録 | W36: 削 | AB36: 22 | AC36: 1 | AD36: 増 | AE36: 22 扶養親族の退職 | AF36: 増 | AG36: 増 | AL36: =IF(A36="","",IF(COUNTIF(A36:A$2001,A36)=1,1,0)) -> 1 | AM36: =IF(I36="","",TODAY()-I36) -> 885 | AN36: =IF(A36="","",IF(AND(E36<>"33 確認済",E36<>"36 送付中"),1,0)) -> 1 | AO36: =IF(A36="","",IF(AG36<>"",1,0)) -> 1
A37: 202460000121 | D37: 40 | E37: 40 差戻し | F37: 20 | G37: 20 差戻し | H37: 45383 | I37: 45386 | J37: 45390 | K37: 45390 | O37: 57 削除待ち登録 | W37: 削 | AB37: 47 | AC37: 0 | AD37: 減 | AE37: 47 扶養親族の就職 | AF37: 減 | AG37: 減 | AH37: 減 | AL37: =IF(A37="","",IF(COUNTIF(A37:A$2001,A37)=1,1,0)) -> 1 | AM37: =IF(I37="","",TODAY()-I37) -> 904 | AN37: =IF(A37="","",IF(AND(E37<>"33 確認済",E37<>"36 送付中"),1,0)) -> 1 | AO37: =IF(A37="","",IF(AG37<>"",1,0)) -> 1
A38: 202460000142 | D38: 40 | E38: 40 差戻し | F38: 20 | G38: 20 差戻し | H38: 45413 | I38: 45386 | J38: 45750 | K38: 45750 | O38: 57 削除待ち登録 | W38: 削 | AB38: 47 | AC38: 0 | AD38: 減 | AE38: 47 扶養親族の就職 | AG38: 減 | AL38: =IF(A38="","",IF(COUNTIF(A38:A$2001,A38)=1,1,0)) -> 1 | AM38: =IF(I38="","",TODAY()-I38) -> 904 | AN38: =IF(A38="","",IF(AND(E38<>"33 確認済",E38<>"36 送付中"),1,0)) -> 1 | AO38: =IF(A38="","",IF(AG38<>"",1,0)) -> 1
A39: 202460000609 | D39: 31 | E39: 31 ＯＰ確認中 | H39: 45296 | I39: 45413 | J39: 45420 | K39: 45425 | O39: 22 担当者変更 | S39: 確 | AB39: 99 | AC39: 1 | AD39: 増 | AE39: 99 その他 | AF39: 増 | AG39: 増 | AH39: 増 | AL39: =IF(A39="","",IF(COUNTIF(A39:A$2001,A39)=1,1,0)) -> 1 | AM39: =IF(I39="","",TODAY()-I39) -> 877 | AN39: =IF(A39="","",IF(AND(E39<>"33 確認済",E39<>"36 送付中"),1,0)) -> 1 | AO39: =IF(A39="","",IF(AG39<>"",1,0)) -> 1
A40: 202460002704 | D40: 32 | E40: 32 ＳＶ確認中 | H40: 45641 | I40: 45642 | J40: 45651 | K40: 45651 | O40: 30 登録 | AB40: 98 | AC40: 0 | AD40: 減 | AE40: 98 年金支給に係る変更 | AG40: 減 | AL40: =IF(A40="","",IF(COUNTIF(A40:A$2001,A40)=1,1,0)) -> 1 | AM40: =IF(I40="","",TODAY()-I40) -> 648 | AN40: =IF(A40="","",IF(AND(E40<>"33 確認済",E40<>"36 送付中"),1,0)) -> 1 | AO40: =IF(A40="","",IF(AG40<>"",1,0)) -> 1
...

Sheet ダッシュボード
B2: 扶養異動申請 進捗ダッシュボード | N2: =TODAY() -> 46290
B4: ▼ 使い方
B5: 手順① | C5: 「元データ」シートを開き、2行目以降に最新データを貼り付ける（ヘッダー行1行目は変更しないこと）
B6: 手順② | C6: データを貼り替える場合は「元データ一括クリア」マクロを実行して既存データを削除してから貼り付ける
B7: 手順③ | C7: 「ダッシュボード」シートに戻ると自動で集計が更新される（TODAY()基準で経過日数も再計算）
B8: 注意 | C8: ★印の黄色列（元データシート右端4列）は作業列のため削除・上書き不可
B9: ⬛ 元データ一括クリア ※マクロ「ClearData」を実行
B11: ▼ 以下の案件を確認してください
B19: ▼ 未完了案件サマリー
B20: 未完了 総件数 | F20: センター対応中 | J20: 差戻し中
B21: =SUMPRODUCT((元データ!$AL$2:$AL$2001=1)*(元データ!$AN$2:$AN$2001=1)) -> 307 | F21: =SUMPRODUCT((元データ!$AL$2:$AL$2001=1)*(元データ!$AN$2:$AN$2001=1))-SUMPRODUCT((元データ!$AL$2:$AL$2001=1)*(元データ!$AN$2:$AN$2001=1)*(元データ!$E$2:$E$2001="40 差戻し")) -> 256 | J21: =SUMPRODUCT((元データ!$AL$2:$AL$2001=1)*(元データ!$AN$2:$AN$2001=1)*(元データ!$E$2:$E$2001="40 差戻し")) -> 51
B23: ▼ ステータス別 件数
B24: ステータス | C24: 総件数 | D24: 申請日から7日以内 | E24: 申請日から8〜14日 | F24: 申請日から15〜21日 | G24: 申請日から1か月超 | H24: 申請日から2か月超
B25: 確認待ち | C25: =SUMPRODUCT((元データ!$AL$2:$AL$2001=1)*(元データ!$AN$2:$AN$2001=1)*(元データ!$E$2:$E$2001="20 確認待ち")) -> 77 | D25: =SUMPRODUCT((元データ!$AL$2:$AL$2001=1)*(元データ!$AN$2:$AN$2001=1)*(元データ!$E$2:$E$2001="20 確認待ち")*(元データ!$AM$2:$AM$2001<=7)) -> 42 | E25: =SUMPRODUCT((元データ!$AL$2:$AL$2001=1)*(元データ!$AN$2:$AN$2001=1)*(元データ!$E$2:$E$2001="20 確認待ち")*(元データ!$AM$2:$AM$2001>=8)*(元データ!$AM$2:$AM$2001<=14)) -> 11 | F25: =SUMPRODUCT((元データ!$AL$2:$AL$2001=1)*(元データ!$AN$2:$AN$2001=1)*(元データ!$E$2:$E$2001="20 確認待ち")*(元データ!$AM$2:$AM$2001>=15)*(元データ!$AM$2:$AM$2001<=21)) -> 3 | G25: =SUMPRODUCT((元データ!$AL$2:$AL$2001=1)*(元データ!$AN$2:$AN$2001=1)*(元データ!$E$2:$E$2001="20 確認待ち")*(元データ!$AM$2:$AM$2001>=22)*(元データ!$AM$2:$AM$2001<=30)) -> 4 | H25: =SUMPRODUCT((元データ!$AL$2:$AL$2001=1)*(元データ!$AN$2:$AN$2001=1)*(元データ!$E$2:$E$2001="20 確認待ち")*(元データ!$AM$2:$AM$2001>=31)) -> 17
B26: 申請受付 | C26: =SUMPRODUCT((元データ!$AL$2:$AL$2001=1)*(元データ!$AN$2:$AN$2001=1)*(元データ!$E$2:$E$2001="30 申請受付")) -> 59 | D26: =SUMPRODUCT((元データ!$AL$2:$AL$2001=1)*(元データ!$AN$2:$AN$2001=1)*(元データ!$E$2:$E$2001="30 申請受付")*(元データ!$AM$2:$AM$2001<=7)) -> 27 | E26: =SUMPRODUCT((元データ!$AL$2:$AL$2001=1)*(元データ!$AN$2:$AN$2001=1)*(元データ!$E$2:$E$2001="30 申請受付")*(元データ!$AM$2:$AM$2001>=8)*(元データ!$AM$2:$AM$2001<=14)) -> 24 | F26: =SUMPRODUCT((元データ!$AL$2:$AL$2001=1)*(元データ!$AN$2:$AN$2001=1)*(元データ!$E$2:$E$2001="30 申請受付")*(元データ!$AM$2:$AM$2001>=15)*(元データ!$AM$2:$AM$2001<=21)) -> 2 | G26: =SUMPRODUCT((元データ!$AL$2:$AL$2001=1)*(元データ!$AN$2:$AN$2001=1)*(元データ!$E$2:$E$2001="30 申請受付")*(元データ!$AM$2:$AM$2001>=22)*(元データ!$AM$2:$AM$2001<=30)) -> 2 | H26: =SUMPRODUCT((元データ!$AL$2:$AL$2001=1)*(元データ!$AN$2:$AN$2001=1)*(元データ!$E$2:$E$2001="30 申請受付")*(元データ!$AM$2:$AM$2001>=31)) -> 4
B27: OP確認中 | C27: =SUMPRODUCT((元データ!$AL$2:$AL$2001=1)*(元データ!$AN$2:$AN$2001=1)*(元データ!$E$2:$E$2001="31 ＯＰ確認中")) -> 77 | D27: =SUMPRODUCT((元データ!$AL$2:$AL$2001=1)*(元データ!$AN$2:$AN$2001=1)*(元データ!$E$2:$E$2001="31 ＯＰ確認中")*(元データ!$AM$2:$AM$2001<=7)) -> 1 | E27: =SUMPRODUCT((元データ!$AL$2:$AL$2001=1)*(元データ!$AN$2:$AN$2001=1)*(元データ!$E$2:$E$2001="31 ＯＰ確認中")*(元データ!$AM$2:$AM$2001>=8)*(元データ!$AM$2:$AM$2001<=14)) -> 31 | F27: =SUMPRODUCT((元データ!$AL$2:$AL$2001=1)*(元データ!$AN$2:$AN$2001=1)*(元データ!$E$2:$E$2001="31 ＯＰ確認中")*(元データ!$AM$2:$AM$2001>=15)*(元データ!$AM$2:$AM$2001<=21)) -> 4 | G27: =SUMPRODUCT((元データ!$AL$2:$AL$2001=1)*(元データ!$AN$2:$AN$2001=1)*(元データ!$E$2:$E$2001="31 ＯＰ確認中")*(元データ!$AM$2:$AM$2001>=22)*(元データ!$AM$2:$AM$2001<=30)) -> 1 | H27: =SUMPRODUCT((元データ!$AL$2:$AL$2001=1)*(元データ!$AN$2:$AN$2001=1)*(元データ!$E$2:$E$2001="31 ＯＰ確認中")*(元データ!$AM$2:$AM$2001>=31)) -> 40
B28: SV確認中 | C28: =SUMPRODUCT((元データ!$AL$2:$AL$2001=1)*(元データ!$AN$2:$AN$2001=1)*(元データ!$E$2:$E$2001="32 ＳＶ確認中")) -> 43 | D28: =SUMPRODUCT((元データ!$AL$2:$AL$2001=1)*(元データ!$AN$2:$AN$2001=1)*(元データ!$E$2:$E$2001="32 ＳＶ確認中")*(元データ!$AM$2:$AM$2001<=7)) -> 0 | E28: =SUMPRODUCT((元データ!$AL$2:$AL$2001=1)*(元データ!$AN$2:$AN$2001=1)*(元データ!$E$2:$E$2001="32 ＳＶ確認中")*(元データ!$AM$2:$AM$2001>=8)*(元データ!$AM$2:$AM$2001<=14)) -> 11 | F28: =SUMPRODUCT((元データ!$AL$2:$AL$2001=1)*(元データ!$AN$2:$AN$2001=1)*(元データ!$E$2:$E$2001="32 ＳＶ確認中")*(元データ!$AM$2:$AM$2001>=15)*(元データ!$AM$2:$AM$2001<=21)) -> 11 | G28: =SUMPRODUCT((元データ!$AL$2:$AL$2001=1)*(元データ!$AN$2:$AN$2001=1)*(元データ!$E$2:$E$2001="32 ＳＶ確認中")*(元データ!$AM$2:$AM$2001>=22)*(元データ!$AM$2:$AM$2001<=30)) -> 4 | H28: =SUMPRODUCT((元データ!$AL$2:$AL$2001=1)*(元データ!$AN$2:$AN$2001=1)*(元データ!$E$2:$E$2001="32 ＳＶ確認中")*(元データ!$AM$2:$AM$2001>=31)) -> 17
B29: 差戻し | C29: =SUMPRODUCT((元データ!$AL$2:$AL$2001=1)*(元データ!$AN$2:$AN$2001=1)*(元データ!$E$2:$E$2001="40 差戻し")) -> 51 | D29: =SUMPRODUCT((元データ!$AL$2:$AL$2001=1)*(元データ!$AN$2:$AN$2001=1)*(元データ!$E$2:$E$2001="40 差戻し")*(元データ!$AM$2:$AM$2001<=7)) -> 0 | E29: =SUMPRODUCT((元データ!$AL$2:$AL$2001=1)*(元データ!$AN$2:$AN$2001=1)*(元データ!$E$2:$E$2001="40 差戻し")*(元データ!$AM$2:$AM$2001>=8)*(元データ!$AM$2:$AM$2001<=14)) -> 2 | F29: =SUMPRODUCT((元データ!$AL$2:$AL$2001=1)*(元データ!$AN$2:$AN$2001=1)*(元データ!$E$2:$E$2001="40 差戻し")*(元データ!$AM$2:$AM$2001>=15)*(元データ!$AM$2:$AM$2001<=21)) -> 2 | G29: =SUMPRODUCT((元データ!$AL$2:$AL$2001=1)*(元データ!$AN$2:$AN$2001=1)*(元データ!$E$2:$E$2001="40 差戻し")*(元データ!$AM$2:$AM$2001>=22)*(元データ!$AM$2:$AM$2001<=30)) -> 7 | H29: =SUMPRODUCT((元データ!$AL$2:$AL$2001=1)*(元データ!$AN$2:$AN$2001=1)*(元データ!$E$2:$E$2001="40 差戻し")*(元データ!$AM$2:$AM$2001>=31)) -> 40
B30: 合計 | C30: =SUMPRODUCT((元データ!$AL$2:$AL$2001=1)*(元データ!$AN$2:$AN$2001=1)) -> 307 | D30: =SUMPRODUCT((元データ!$AL$2:$AL$2001=1)*(元データ!$AN$2:$AN$2001=1)*(元データ!$AM$2:$AM$2001<=7)) -> 70 | E30: =SUMPRODUCT((元データ!$AL$2:$AL$2001=1)*(元データ!$AN$2:$AN$2001=1)*(元データ!$AM$2:$AM$2001>=8)*(元データ!$AM$2:$AM$2001<=14)) -> 79 | F30: =SUMPRODUCT((元データ!$AL$2:$AL$2001=1)*(元データ!$AN$2:$AN$2001=1)*(元データ!$AM$2:$AM$2001>=15)*(元データ!$AM$2:$AM$2001<=21)) -> 22 | G30: =SUMPRODUCT((元データ!$AL$2:$AL$2001=1)*(元データ!$AN$2:$AN$2001=1)*(元データ!$AM$2:$AM$2001>=22)*(元データ!$AM$2:$AM$2001<=30)) -> 18 | H30: =SUMPRODUCT((元データ!$AL$2:$AL$2001=1)*(元データ!$AN$2:$AN$2001=1)*(元データ!$AM$2:$AM$2001>=31)) -> 118
B32: ▼ 事由別 件数（共済あり／なし）
B33: 優先順位 | C33: 事由 | D33: 共済 | E33: 総件数 | F33: 申請日から7日以内 | H33: 申請日から8〜14日 | J33: 申請日から15〜21日 | L33: 申請日から1か月超 | N33: 申請日から2か月超
F34: 件数（ステータス内訳） | G34: 申請番号（フラグ） | H34: 件数（ステータス内訳） | I34: 申請番号（フラグ） | J34: 件数（ステータス内訳） | K34: 申請番号（フラグ） | L34: 件数（ステータス内訳） | M34: 申請番号（フラグ） | N34: 件数（ステータス内訳） | O34: 申請番号（フラグ）
C35: 21 出生 | D35: あり | E35: =SUMPRODUCT((元データ!$AL$2:$AL$2001=1)*(元データ!$AN$2:$AN$2001=1)*(元データ!$AE$2:$AE$2001=$C$35)*(元データ!$AO$2:$AO$2001=1)) -> 30 | F35: 3件 確認待:3 | G35: 202660001446（添待ち） 202660001485（添待ち） 202660001489（添待ち） | H35: 12件 確認待:2 / OP:7 / SV:3 | I35: 202660001313 202660001327 202660001345 202660001351 202660001363 202660001365 202660001369 202660001375 202660001396（添待ち） 202660001434（添待ち） 202660001451 202660001461 | J35: 4件 確認待:2 / OP:1 / SV:1 | K35: 202660001331 202660001334（添待ち） 202660001337（添待ち） 202660001349 | L35: 4件 確認待:1 / SV:1 / 差戻:2 | M35: 202660001253 202660001270（添待ち） 202660001271（添待ち） 202660001310（削除） | N35: 7件 確認待:1 / OP:1 / SV:2 / 差戻:3 | O35: 200960002933 201860001388（添待ち、SV） 202660001033 202660001060（添待ち） 202660001153（添待ち） 202660001203 202660001211（添待ち）
D36: なし | E36: =SUMPRODUCT((元データ!$AL$2:$AL$2001=1)*(元データ!$AN$2:$AN$2001=1)*(元データ!$AE$2:$AE$2001=$C$35)*(元データ!$AO$2:$AO$2001=0)) -> 4 | F36: - | G36: - | H36: 1件 確認待:1 | I36: 202660001414（添待ち） | J36: 1件 OP:1 | K36: 202660001307 | L36: - | M36: - | N36: 2件 OP:1 / SV:1 | O36: 202660001115 202660001212
C37: 23 結婚 | D37: あり | E37: =SUMPRODUCT((元データ!$AL$2:$AL$2001=1)*(元データ!$AN$2:$AN$2001=1)*(元データ!$AE$2:$AE$2001=$C$37)*(元データ!$AO$2:$AO$2001=1)) -> 2 | F37: - | G37: - | H37: - | I37: - | J37: - | K37: - | L37: - | M37: - | N37: 2件 差戻:2 | O37: 201360002263（削除） 202560002505（添待ち）
D38: なし | E38: =SUMPRODUCT((元データ!$AL$2:$AL$2001=1)*(元データ!$AN$2:$AN$2001=1)*(元データ!$AE$2:$AE$2001=$C$37)*(元データ!$AO$2:$AO$2001=0)) -> 46 | F38: 15件 確認待:5 / 受付:10 | G38: 202660001462 202660001463 202660001466 202660001468 202660001474 202660001477 202660001496 202660001505 202660001514 202660001516 202660001525 202660001530 202660001540 202660001543 202660001544 | H38: 19件 受付:6 / OP:11 / SV:2 | I38: 202660001356 202660001359 202660001361 202660001366 202660001368 202660001371 202660001373 202660001376 202660001379 202660001380 202660001385 202660001398 202660001401 202660001424 202660001428 202660001439 202660001450 202660001453 202660001457 | J38: 3件 SV:3 | K38: 202660001321 202660001328 202660001338 | L38: - | M38: - | N38: 9件 確認待:1 / OP:5 / SV:1 / 差戻:2 | O38: 200960002795 200960003028（確認事項） 202360003320 202460003283 202560002534（削除） 202660000721（確認事項） 202660000808 202660001204 202660001209
C39: 30 養子縁組 | D39: あり | E39: =SUMPRODUCT((元データ!$AL$2:$AL$2001=1)*(元データ!$AN$2:$AN$2001=1)*(元データ!$AE$2:$AE$2001=$C$39)*(元データ!$AO$2:$AO$2001=1)) -> 1 | F39: 1件 確認待:1 | G39: 202660001492（添待ち） | H39: - | I39: - | J39: - | K39: - | L39: - | M39: - | N39: - | O39: -
D40: なし | E40: =SUMPRODUCT((元データ!$AL$2:$AL$2001=1)*(元データ!$AN$2:$AN$2001=1)*(元データ!$AE$2:$AE$2001=$C$39)*(元データ!$AO$2:$AO$2001=0)) -> 0 | F40: - | G40: - | H40: - | I40: - | J40: - | K40: - | L40: - | M40: - | N40: - | O40: -
C41: 55 扶養親族の結婚 | D41: あり | E41: =SUMPRODUCT((元データ!$AL$2:$AL$2001=1)*(元データ!$AN$2:$AN$2001=1)*(元データ!$AE$2:$AE$2001=$C$41)*(元データ!$AO$2:$AO$2001=1)) -> 1 | F41: - | G41: - | H41: - | I41: - | J41: - | K41: - | L41: - | M41: - | N41: 1件 受付:1 | O41: 202660001121
D42: なし | E42: =SUMPRODUCT((元データ!$AL$2:$AL$2001=1)*(元データ!$AN$2:$AN$2001=1)*(元データ!$AE$2:$AE$2001=$C$41)*(元データ!$AO$2:$AO$2001=0)) -> 0 | F42: - | G42: - | H42: - | I42: - | J42: - | K42: - | L42: - | M42: - | N42: - | O42: -
C43: 22 扶養親族の退職 | D43: あり | E43: =SUMPRODUCT((元データ!$AL$2:$AL$2001=1)*(元データ!$AN$2:$AN$2001=1)*(元データ!$AE$2:$AE$2001=$C$43)*(元データ!$AO$2:$AO$2001=1)) -> 21 | F43: 2件 確認待:2 | G43: 202660001362（添待ち） 202660001459（添待ち） | H43: 2件 確認待:2 | I43: 202660001354（添待ち） 202660001377（添待ち） | J43: - | K43: - | L43: 1件 差戻:1 | M43: 202660001233 | N43: 16件 確認待:3 / OP:7 / SV:2 / 差戻:4 | O43: 200860002058 201260002213 201260002232 202060000569 202460000110（削除） 202460002924（削除） 202560000569（削除） 202560001758 202660000850（確認事項） 202660001026（添待ち、SV） 202660001080（添待ち） 202660001090（添待ち） 202660001131（確認事項） 202660001183（添待ち） 202660001217（確認事項） 202660001231
D44: なし | E44: =SUMPRODUCT((元データ!$AL$2:$AL$2001=1)*(元データ!$AN$2:$AN$2001=1)*(元データ!$AE$2:$AE$2001=$C$43)*(元データ!$AO$2:$AO$2001=0)) -> 1 | F44: 1件 確認待:1 | G44: 202660001469（添待ち） | H44: - | I44: - | J44: - | K44: - | L44: - | M44: - | N44: - | O44: -
C45: 24 雇用保険受給終了 | D45: あり | E45: =SUMPRODUCT((元データ!$AL$2:$AL$2001=1)*(元データ!$AN$2:$AN$2001=1)*(元データ!$AE$2:$AE$2001=$C$45)*(元データ!$AO$2:$AO$2001=1)) -> 6 | F45: 3件 確認待:3 | G45: 202660001358（添待ち） 202660001488（添待ち） 202660001532 | H45: 1件 OP:1 | I45: 202660001442 | J45: - | K45: - | L45: - | M45: - | N45: 2件 確認待:2 | O45: 202660000834（確認事項） 202660001173（添待ち）
D46: なし | E46: =SUMPRODUCT((元データ!$AL$2:$AL$2001=1)*(元データ!$AN$2:$AN$2001=1)*(元データ!$AE$2:$AE$2001=$C$45)*(元データ!$AO$2:$AO$2001=0)) -> 1 | F46: - | G46: - | H46: - | I46: - | J46: 1件 SV:1 | K46: 202660001319 | L46: - | M46: - | N46: - | O46: -
C47: 27 収入限度額以下 | D47: あり | E47: =SUMPRODUCT((元データ!$AL$2:$AL$2001=1)*(元データ!$AN$2:$AN$2001=1)*(元データ!$AE$2:$AE$2001=$C$47)*(元データ!$AO$2:$AO$2001=1)) -> 8 | F47: 1件 確認待:1 | G47: 202660001521 | H47: 1件 SV:1 | I47: 202660001407 | J47: - | K47: - | L47: - | M47: - | N47: 6件 確認待:1 / SV:2 / 差戻:3 | O47: 202060001460（添待ち） 202060002466（発信、削除） 202560002767（添待ち） 202660000682（添待ち） 202660000762（発信、SV） 202660001171（添待ち）
D48: なし | E48: =SUMPRODUCT((元データ!$AL$2:$AL$2001=1)*(元データ!$AN$2:$AN$2001=1)*(元データ!$AE$2:$AE$2001=$C$47)*(元データ!$AO$2:$AO$2001=0)) -> 5 | F48: 4件 確認待:4 | G48: 202660001473（添待ち） 202660001483（添待ち） 202660001537 202660001539 | H48: - | I48: - | J48: - | K48: - | L48: - | M48: - | N48: 1件 差戻:1 | O48: 201760002086（削除）
C49: 25 育休 | D49: あり | E49: =SUMPRODUCT((元データ!$AL$2:$AL$2001=1)*(元データ!$AN$2:$AN$2001=1)*(元データ!$AE$2:$AE$2001=$C$49)*(元データ!$AO$2:$AO$2001=1)) -> 1 | F49: - | G49: - | H49: - | I49: - | J49: - | K49: - | L49: - | M49: - | N49: 1件 差戻:1 | O49: 202660000490（添待ち）
D50: なし | E50: =SUMPRODUCT((元データ!$AL$2:$AL$2001=1)*(元データ!$AN$2:$AN$2001=1)*(元データ!$AE$2:$AE$2001=$C$49)*(元データ!$AO$2:$AO$2001=0)) -> 12 | F50: 4件 確認待:4 | G50: 202660001370（添待ち） 202660001460（添待ち） 202660001491（添待ち） 202660001541 | H50: 5件 確認待:3 / OP:2 | I50: 202660001393 202660001399（添待ち） 202660001411（添待ち） 202660001425 202660001444（添待ち） | J50: - | K50: - | L50: - | M50: - | N50: 3件 OP:2 / 差戻:1 | O50: 200960002929 202560002878（添待ち） 202660001352（SV）
C51: 26 扶養者の変更 | D51: あり | E51: =SUMPRODUCT((元データ!$AL$2:$AL$2001=1)*(元データ!$AN$2:$AN$2001=1)*(元データ!$AE$2:$AE$2001=$C$51)*(元データ!$AO$2:$AO$2001=1)) -> 14 | F51: 2件 確認待:2 | G51: 202660001484（添待ち） 202660001531 | H51: 1件 OP:1 | I51: 202660001423 | J51: 1件 SV:1 | K51: 202660001262 | L51: 1件 差戻:1 | M51: 202660001298（添待ち） | N51: 9件 確認待:2 / OP:6 / 差戻:1 | O51: 200960002999 201260002479 202660000578（確認事項） 202660000703（添待ち） 202660001000（添待ち） 202660001008（添待ち、SV） 202660001083 202660001165（SV） 202660001221
D52: なし | E52: =SUMPRODUCT((元データ!$AL$2:$AL$2001=1)*(元データ!$AN$2:$AN$2001=1)*(元データ!$AE$2:$AE$2001=$C$51)*(元データ!$AO$2:$AO$2001=0)) -> 4 | F52: - | G52: - | H52: 1件 確認待:1 | I52: 202660001433（添待ち） | J52: 2件 SV:1 / 差戻:1 | K52: 202660001342（添待ち） 202660001350 | L52: - | M52: - | N52: 1件 差戻:1 | O52: 202660000466（削除）
...

Sheet VBAコード
B2: VBAコード ― 元データ一括クリア ― 設定手順
B3: 手順① Excelでこのファイルを開いた状態で Alt+F11 を押す（VBAエディタが開く）
B4: 手順② メニューバーの「挿入」→「標準モジュール」をクリック
B5: 手順③ 下のコードをすべてコピーして貼り付ける
B6: 手順④ Ctrl+S で保存（「マクロが含まれています」と表示されたら「はい」を選択）
B7: 手順⑤ VBAエディタを閉じて「ダッシュボード」シートに戻る
B8: 手順⑥ 赤いセル「⬛ 元データ一括クリア」を右クリック → 「マクロの登録」→「ClearData」を選択 → OK
B11: ▼ コード（下記をすべてコピーしてVBAエディタに貼り付ける）
B12: Sub ClearData()
B13: Dim ws As Worksheet
B14: Dim lastRow As Long
B15: Set ws = ThisWorkbook.Sheets("元データ")
... B28: End Sub
